<robot name="HVAC2023_athletics_field">
  <link name="Base">
    <visual>
      <geometry>
        <mesh
          filename="../../../../choreonoid/share/choreonoid-2.2/model/field2023/2023_hvac_stage.obj" />
      </geometry>
    </visual>
    <collision>
      <geometry>
        <mesh
          filename="../../../../choreonoid/share/choreonoid-2.2/model/field2023/field2023_athletics-cliff-1.STL" />
      </geometry>
    </collision>
    <collision>
      <geometry>
        <mesh
          filename="../../../../choreonoid/share/choreonoid-2.2/model/field2023/field2023_athletics-curve-1.STL" />
      </geometry>
    </collision>
    <collision>
      <geometry>
        <mesh
          filename="../../../../choreonoid/share/choreonoid-2.2/model/field2023/field2023_athletics-goal0-1.STL" />
      </geometry>
    </collision>
    <collision>
      <geometry>
        <mesh
          filename="../../../../choreonoid/share/choreonoid-2.2/model/field2023/field2023_athletics-goal1-1.STL" />
      </geometry>
    </collision>
    <collision>
      <geometry>
        <mesh
          filename="../../../../choreonoid/share/choreonoid-2.2/model/field2023/field2023_athletics-goal1-2.STL" />
      </geometry>
    </collision>
    <collision>
      <geometry>
        <mesh
          filename="../../../../choreonoid/share/choreonoid-2.2/model/field2023/field2023_athletics-goal1-3.STL" />
      </geometry>
    </collision>
    <collision>
      <geometry>
        <mesh
          filename="../../../../choreonoid/share/choreonoid-2.2/model/field2023/field2023_athletics-intermediate_step-2.STL" />
      </geometry>
    </collision>
    <collision>
      <geometry>
        <mesh
          filename="../../../../choreonoid/share/choreonoid-2.2/model/field2023/field2023_athletics-intermediate_step-3.STL" />
      </geometry>
    </collision>
    <collision>
      <geometry>
        <mesh
          filename="../../../../choreonoid/share/choreonoid-2.2/model/field2023/field2023_athletics-slope-1.STL" />
      </geometry>
    </collision>
    <collision>
      <geometry>
        <mesh
          filename="../../../../choreonoid/share/choreonoid-2.2/model/field2023/field2023_athletics-stair-1.STL" />
      </geometry>
    </collision>
    <collision>
      <geometry>
        <mesh
          filename="../../../../choreonoid/share/choreonoid-2.2/model/field2023/field2023_athletics-start0-1.STL" />
      </geometry>
    </collision>
    <collision>
      <geometry>
        <mesh
          filename="../../../../choreonoid/share/choreonoid-2.2/model/field2023/field2023_athletics-start1-2.STL" />
      </geometry>
    </collision>
    <collision>
      <geometry>
        <mesh
          filename="../../../../choreonoid/share/choreonoid-2.2/model/field2023/field2023_athletics-step_right-1.STL" />
      </geometry>
    </collision>
    <collision>
      <geometry>
        <mesh
          filename="../../../../choreonoid/share/choreonoid-2.2/model/field2023/field2023_athletics-step_right-2.STL" />
      </geometry>
    </collision>
    <collision>
      <geometry>
        <mesh
          filename="../../../../choreonoid/share/choreonoid-2.2/model/field2023/field2023_athletics-step_right-3.STL" />
      </geometry>
    </collision>
    <collision>
      <geometry>
        <mesh
          filename="../../../../choreonoid/share/choreonoid-2.2/model/field2023/field2023_athletics-step_right-4.STL" />
      </geometry>
    </collision>
  </link>

  <link name="Prop1">
    <visual>
      <geometry>
        <mesh
          filename="../../../../choreonoid/share/choreonoid-2.2/model/field2023/2023_hvac_stage_frame1.obj" />
      </geometry>
    </visual>
  </link>
  <joint name="Prop1_joint" type="fixed">
    <parent link="Base" />
    <child link="Prop1" />
  </joint>

  <link name="Link1">
    <visual>
      <origin xyz="0 0 -0.495" />
      <geometry>
        <mesh
          filename="../../../../choreonoid/share/choreonoid-2.2/model/field2023/link1.STL" />
      </geometry>
    </visual>
    <collision>
      <origin xyz="0 0 -0.495" />
      <geometry>
        <box size="0.04 0.04 1.03" />
      </geometry>
    </collision>
    <inertial>
      <origin xyz="0 0 -0.495" />
      <mass value="10" />
      <inertia ixx="0.88542" ixy="0" ixz="0" iyy="0.88542" iyz="0" izz="0.0026667" />
    </inertial>
  </link>
  <joint name="Link1_joint" type="revolute">
    <parent link="Prop1" />
    <child link="Link1" />
    <origin xyz="1.7859 -1.380 1.050" />
    <axis xyz="0 1 0" />
    <limit effort="100" velocity="1.0" lower="-1.5707" upper="1.5707" />
  </joint>

  <link name="Prop2">
    <visual>
      <geometry>
        <mesh
          filename="../../../../choreonoid/share/choreonoid-2.2/model/field2023/2023_hvac_stage_frame2.obj" />
      </geometry>
    </visual>
  </link>
  <joint name="Prop2_joint" type="fixed">
    <parent link="Base" />
    <child link="Prop2" />
  </joint>

  <link name="Link2">
    <visual>
      <origin xyz="0 0 -0.495" />
      <geometry>
        <mesh
          filename="../../../../choreonoid/share/choreonoid-2.2/model/field2023/link1.STL" />
      </geometry>
    </visual>
    <collision>
      <origin xyz="0 0 -0.495" />
      <geometry>
        <box size="0.04 0.04 1.03" />
      </geometry>
    </collision>
    <inertial>
      <origin xyz="0 0 -0.495" />
      <mass value="10" />
      <inertia ixx="0.88542" ixy="0" ixz="0" iyy="0.88542" iyz="0" izz="0.0026667" />
    </inertial>
  </link>
  <joint name="Link2_joint" type="revolute">
    <parent link="Prop2" />
    <child link="Link2" />
    <origin xyz="1.7859 -0.63486 1.050" />
    <axis xyz="0 1 0" />
    <limit effort="100" velocity="1.0" lower="-1.5707" upper="1.5707" />
  </joint>

  <link name="Prop3">
    <visual>
      <geometry>
        <mesh
          filename="../../../../choreonoid/share/choreonoid-2.2/model/field2023/2023_hvac_stage_frame3.obj" />
      </geometry>
    </visual>
  </link>
  <joint name="Prop3_joint" type="fixed">
    <parent link="Base" />
    <child link="Prop3" />
  </joint>

  <link name="Link3">
    <visual>
      <origin xyz="0 0 -0.495" />
      <geometry>
        <mesh
          filename="../../../../choreonoid/share/choreonoid-2.2/model/field2023/link1.STL" />
      </geometry>
    </visual>
    <collision>
      <origin xyz="0 0 -0.495" />
      <geometry>
        <box size="0.04 0.04 1.03" />
      </geometry>
    </collision>
    <inertial>
      <origin xyz="0 0 -0.495" />
      <mass value="10" />
      <inertia ixx="0.88542" ixy="0" ixz="0" iyy="0.88542" iyz="0" izz="0.0026667" />
    </inertial>
  </link>
  <joint name="Link3_joint" type="revolute">
    <parent link="Prop3" />
    <child link="Link3" />
    <origin xyz="3.7859 -1.380 1.050" />
    <axis xyz="0 1 0" />
    <limit effort="100" velocity="1.0" lower="-1.5707" upper="1.5707" />
  </joint>

  <link name="Prop4">
    <visual>
      <geometry>
        <mesh
          filename="../../../../choreonoid/share/choreonoid-2.2/model/field2023/2023_hvac_stage_frame4.obj" />
      </geometry>
    </visual>
  </link>
  <joint name="Prop4_joint" type="fixed">
    <parent link="Base" />
    <child link="Prop4" />
  </joint>

  <link name="Link4">
    <visual>
      <origin xyz="0 0 -0.495" />
      <geometry>
        <mesh
          filename="../../../../choreonoid/share/choreonoid-2.2/model/field2023/link1.STL" />
      </geometry>
    </visual>
    <collision>
      <origin xyz="0 0 -0.495" />
      <geometry>
        <box size="0.04 0.04 1.03" />
      </geometry>
    </collision>
    <inertial>
      <origin xyz="0 0 -0.495" />
      <mass value="10" />
      <inertia ixx="0.88542" ixy="0" ixz="0" iyy="0.88542" iyz="0" izz="0.0026667" />
    </inertial>
  </link>
  <joint name="Link4_joint" type="revolute">
    <parent link="Prop4" />
    <child link="Link4" />
    <origin xyz="3.7859 -0.63486 1.050" />
    <axis xyz="0 1 0" />
    <limit effort="100" velocity="1.0" lower="-1.5707" upper="1.5707" />
  </joint>

  <link name="MovablePlate">
    <visual>
      <origin xyz="1.0 0.35 0" />
      <geometry>
        <mesh
          filename="../../../../choreonoid/share/choreonoid-2.2/model/field2023/movable_plate.STL" />
      </geometry>
    </visual>
    <collision>
      <origin xyz="1.0 0.35 0" />
      <geometry>
        <box size="3.0 0.7 0.1" />
      </geometry>
    </collision>
    <inertial>
      <origin xyz="1.0 0.35 0" />
      <mass value="30" />
      <inertia ixx="1.25" ixy="0" ixz="0" iyy="22.525" iyz="0" izz="23.725" />
    </inertial>
  </link>
  <!-- <joint name="MovablePlate_joint1" type="revolute">
    <parent link="Link1" />
    <child link="MovablePlate" />
    <origin xyz="0 0.02 -0.99" />
    <axis xyz="0 1 0" />
    <limit effort="100" velocity="1.0" lower="-1.5707" upper="1.5707" />
  </joint> -->
  <joint name="MovablePlate_joint1" type="fixed">
    <parent link="Prop1" />
    <child link="MovablePlate" />
    <origin xyz="1.7859 -1.36 0.06" />
  </joint>
</robot>
